<?xml version="1.0" encoding="utf-8"?>
<robot name="drone">
<link name="base_link">
    <inertial>
        <origin xyz="0 0 0" rpy="0 0 0"/>
        <mass value="1.543"/>
        <inertia ixx="0.0206" ixy="0.0" ixz="0.0" iyy="0.0210" iyz="0.0" izz="0.0297"/>
    </inertial>
    <visual>
        <origin xyz="0 0 0" rpy="1.5708 0 0"/>
        <geometry>
            <mesh filename="/home/ros_workspace/src/x500_py/models/X500_drone.stl"/>
        </geometry>
        <material name="blue">
            <color rgba="0 0 1 1"/>
        </material>
    </visual>
    <collision>
        <origin xyz="0 0 0" rpy="0 0 0"/>
        <geometry>
            <box size="0.41 0.41 0.8"/>
        </geometry>
    </collision>
</link>

<link name="imu_link">
    <inertial>
        <mass value="0.015"/>
        <inertia ixx="1e-05" ixy="0.0" ixz="0.0" iyy="1e-05" iyz="0.0" izz="1e-05"/>
    </inertial>
</link>

<joint name="imu_joint" type="revolute">
    <parent link="base_link"/>
    <child link="imu_link"/>
    <origin xyz="0 0 0.02" rpy="0 0 0"/>
    <axis xyz="1 0 0"/>
    <limit effort="0" velocity="0" lower="0" upper="0"/>
</joint>

<link name="rotor_0">
    <inertial>
        <mass value="0.005"/>
        <inertia ixx="9.75e-07" ixy="0.0" ixz="0.0" iyy="0.000273104" iyz="0.0" izz="0.000274004"/>
    </inertial>
    <collision>
        <origin xyz="0 0 0" rpy="0 0 0"/>
        <geometry>
            <cylinder radius="0.128" length="0.005"/>
        </geometry>
    </collision>
    <visual>
        <origin xyz="0 0 0" rpy="0 0 0"/>
        <geometry>
            <mesh filename="/home/ros_workspace/src/x500_py/models/iris_prop_ccw.dae"/>
        </geometry>
        <material name="black">
            <color rgba="0 0 0 1"/>
        </material>
    </visual>
</link>
<joint name="rotor_0_joint" type="continuous">
    <parent link="base_link"/>
    <child link="rotor_0"/>
    <origin xyz="0.176 -0.176 0.056" rpy="0 0 0"/>
    <axis xyz="0 0 1"/>
</joint>

<link name="rotor_1">
    <inertial>
        <mass value="0.005"/>
        <inertia ixx="9.75e-07" ixy="0.0" ixz="0.0" iyy="0.000273104" iyz="0.0" izz="0.000274004"/>
    </inertial>
    <collision>
        <origin xyz="0 0 0" rpy="0 0 0"/>
        <geometry>
            <cylinder radius="0.128" length="0.005"/>
        </geometry>
    </collision>
    <visual>
        <origin xyz="0 0 0" rpy="0 0 0"/>
        <geometry>
            <mesh filename="/home/ros_workspace/src/x500_py/models/iris_prop_ccw.dae"/>
        </geometry>
        <material name="black">
            <color rgba="0 0 0 1"/>
        </material>
    </visual>
</link>
<joint name="rotor_1_joint" type="continuous">
    <parent link="base_link"/>
    <child link="rotor_1"/>
    <origin xyz="-0.176 0.176 0.056" rpy="0 0 0"/>
    <axis xyz="0 0 1"/>
</joint>

<link name="rotor_2">
    <inertial>
        <mass value="0.005"/>
        <inertia ixx="9.75e-07" ixy="0.0" ixz="0.0" iyy="0.000273104" iyz="0.0" izz="0.000274004"/>
    </inertial>
    <collision>
        <origin xyz="0 0 0" rpy="0 0 0"/>
        <geometry>
            <cylinder radius="0.128" length="0.005"/>
        </geometry>
    </collision>
    <visual>
        <origin xyz="0 0 0" rpy="0 0 0"/>
        <geometry>
            <mesh filename="/home/ros_workspace/src/x500_py/models/iris_prop_cw.dae"/>
        </geometry>
        <material name="black">
            <color rgba="0 0 0 1"/>
        </material>
    </visual>
</link>
<joint name="rotor_2_joint" type="continuous">
    <parent link="base_link"/>
    <child link="rotor_2"/>
    <origin xyz="0.176 0.176 0.056" rpy="0 0 0"/>
    <axis xyz="0 0 1"/>
</joint>

<link name="rotor_3">
    <inertial>
        <mass value="0.005"/>
        <inertia ixx="9.75e-07" ixy="0.0" ixz="0.0" iyy="0.000273104" iyz="0.0" izz="0.000274004"/>
    </inertial>
    <collision>
        <origin xyz="0 0 0" rpy="0 0 0"/>
        <geometry>
            <cylinder radius="0.128" length="0.005"/>
        </geometry>
    </collision>
    <visual>
        <origin xyz="0 0 0" rpy="0 0 0"/>
        <geometry>
            <mesh filename="/home/ros_workspace/src/x500_py/models/iris_prop_cw.dae"/>
        </geometry>
        <material name="black">
            <color rgba="0 0 0 1"/>
        </material>
    </visual>
</link>
<joint name="rotor_3_joint" type="continuous">
    <parent link="base_link"/>
    <child link="rotor_3"/>
    <origin xyz="-0.176 -0.176 0.056" rpy="0 0 0"/>
    <axis xyz="0 0 1"/>
</joint>

<gazebo>
  <plugin name='rosbag' filename='libgazebo_multirotor_base_plugin.so'>
    <robotNamespace/>
    <linkName>base_link</linkName>
    <rotorVelocitySlowdownSim>10</rotorVelocitySlowdownSim>
  </plugin>
</gazebo>

<gazebo>
  <plugin name='front_right_motor_model' filename='libgazebo_motor_model.so'>
    <robotNamespace/>
    <jointName>rotor_0_joint</jointName>
    <linkName>rotor_0</linkName>
    <turningDirection>ccw</turningDirection>
    <timeConstantUp>0.0125</timeConstantUp>
    <timeConstantDown>0.025</timeConstantDown>
    <maxRotVelocity>1100</maxRotVelocity>
    <motorConstant>5.84e-06</motorConstant>
    <momentConstant>0.06</momentConstant>
    <commandSubTopic>/gazebo/command/motor_speed</commandSubTopic>
    <motorNumber>0</motorNumber>
    <rotorDragCoefficient>0.000175</rotorDragCoefficient>
    <rollingMomentCoefficient>1e-06</rollingMomentCoefficient>
    <motorSpeedPubTopic>/motor_speed/0</motorSpeedPubTopic>
    <rotorVelocitySlowdownSim>10</rotorVelocitySlowdownSim>
  </plugin>
</gazebo>
<gazebo>
  <plugin name='back_left_motor_model' filename='libgazebo_motor_model.so'>
    <robotNamespace/>
    <jointName>rotor_1_joint</jointName>
    <linkName>rotor_1</linkName>
    <turningDirection>ccw</turningDirection>
    <timeConstantUp>0.0125</timeConstantUp>
    <timeConstantDown>0.025</timeConstantDown>
    <maxRotVelocity>1100</maxRotVelocity>
    <motorConstant>5.84e-06</motorConstant>
    <momentConstant>0.06</momentConstant>
    <commandSubTopic>/gazebo/command/motor_speed</commandSubTopic>
    <motorNumber>1</motorNumber>
    <rotorDragCoefficient>0.000175</rotorDragCoefficient>
    <rollingMomentCoefficient>1e-06</rollingMomentCoefficient>
    <motorSpeedPubTopic>/motor_speed/1</motorSpeedPubTopic>
    <rotorVelocitySlowdownSim>10</rotorVelocitySlowdownSim>
  </plugin>
</gazebo>
<gazebo>
  <plugin name='front_left_motor_model' filename='libgazebo_motor_model.so'>
    <robotNamespace/>
    <jointName>rotor_2_joint</jointName>
    <linkName>rotor_2</linkName>
    <turningDirection>cw</turningDirection>
    <timeConstantUp>0.0125</timeConstantUp>
    <timeConstantDown>0.025</timeConstantDown>
    <maxRotVelocity>1100</maxRotVelocity>
    <motorConstant>5.84e-06</motorConstant>
    <momentConstant>0.06</momentConstant>
    <commandSubTopic>/gazebo/command/motor_speed</commandSubTopic>
    <motorNumber>2</motorNumber>
    <rotorDragCoefficient>0.000175</rotorDragCoefficient>
    <rollingMomentCoefficient>1e-06</rollingMomentCoefficient>
    <motorSpeedPubTopic>/motor_speed/2</motorSpeedPubTopic>
    <rotorVelocitySlowdownSim>10</rotorVelocitySlowdownSim>
  </plugin>
</gazebo>
<gazebo>
  <plugin name='back_right_motor_model' filename='libgazebo_motor_model.so'>
    <robotNamespace/>
    <jointName>rotor_3_joint</jointName>
    <linkName>rotor_3</linkName>
    <turningDirection>cw</turningDirection>
    <timeConstantUp>0.0125</timeConstantUp>
    <timeConstantDown>0.025</timeConstantDown>
    <maxRotVelocity>1100</maxRotVelocity>
    <motorConstant>5.84e-06</motorConstant>
    <momentConstant>0.06</momentConstant>
    <commandSubTopic>/gazebo/command/motor_speed</commandSubTopic>
    <motorNumber>3</motorNumber>
    <rotorDragCoefficient>0.000175</rotorDragCoefficient>
    <rollingMomentCoefficient>1e-06</rollingMomentCoefficient>
    <motorSpeedPubTopic>/motor_speed/3</motorSpeedPubTopic>
    <rotorVelocitySlowdownSim>10</rotorVelocitySlowdownSim>
  </plugin>
</gazebo>

<link name="gps0_link">
    <inertial>
        <mass value="0.02"/>
        <inertia ixx="1e-05" ixy="0.0" ixz="0.0" iyy="1e-05" iyz="0.0" izz="1e-05"/>
    </inertial>
</link>
<joint name="gps0_joint" type="fixed">
    <parent link="base_link"/>
    <child link="gps0_link"/>
    <origin xyz="0.05 0 0.04" rpy="0 0 0"/>
</joint>

<gazebo reference="base_link">
  <sensor name="gps" type="gps">
    <pose>0.05 0 0.04 0 0 0</pose>
    <update_rate>5.0</update_rate>
    <always_on>true</always_on>
    <visualize>false</visualize>
    <plugin name="gps_plugin" filename="libgazebo_gps_plugin.so">
      <robotNamespace/>
      <gpsNoise>true</gpsNoise>
      <gpsXYRandomWalk>2.0</gpsXYRandomWalk>
      <gpsZRandomWalk>4.0</gpsZRandomWalk>
      <gpsXYNoiseDensity>2.0e-4</gpsXYNoiseDensity>
      <gpsZNoiseDensity>4.0e-4</gpsZNoiseDensity>
      <gpsVXYNoiseDensity>0.2</gpsVXYNoiseDensity>
      <gpsVZNoiseDensity>0.4</gpsVZNoiseDensity>
    </plugin>
  </sensor>
</gazebo>

<gazebo>
  <plugin name='groundtruth_plugin' filename='libgazebo_groundtruth_plugin.so'>
    <robotNamespace/>
  </plugin>
</gazebo>

<gazebo>
  <plugin name='magnetometer_plugin' filename='libgazebo_magnetometer_plugin.so'>
    <robotNamespace/>
    <pubRate>100</pubRate>
    <linkName>base_link</linkName>
    <noiseDensity>0.0004</noiseDensity>
    <randomWalk>6.4e-06</randomWalk>
    <biasCorrelationTime>600</biasCorrelationTime>
    <magTopic>/mag</magTopic>
  </plugin>
</gazebo>

<gazebo>
  <plugin name='barometer_plugin' filename='libgazebo_barometer_plugin.so'>
    <robotNamespace/>
    <pubRate>50</pubRate>
    <baroTopic>/baro</baroTopic>
    <linkName>base_link</linkName>
    <baroDriftPaPerSec>0</baroDriftPaPerSec>
  </plugin>
</gazebo>
<gazebo>
  <plugin name='rotors_gazebo_imu_plugin' filename='libgazebo_imu_plugin.so'>
    <robotNamespace/>
    <linkName>imu_link</linkName>
    <imuTopic>/imu</imuTopic>
  </plugin>
</gazebo>

<gazebo>
  <plugin name='mavlink_interface' filename='libgazebo_mavlink_interface.so'>
    <robotNamespace/>
    <imuSubTopic>/imu</imuSubTopic>
    <magSubTopic>/mag</magSubTopic>
    <baroSubTopic>/baro</baroSubTopic>
    <!-- <targetGpsSubTopic>drone1/base_link/gps</targetGpsSubTopic> -->
    <mavlink_addr>INADDR_ANY</mavlink_addr>
    <mavlink_tcp_port>4560</mavlink_tcp_port>
    <mavlink_udp_port>14560</mavlink_udp_port>
    <serialEnabled>0</serialEnabled>
    <serialDevice>/dev/ttyACM0</serialDevice>
    <baudRate>921600</baudRate>
    <qgc_addr>INADDR_ANY</qgc_addr>
    <qgc_udp_port>14550</qgc_udp_port>
    <sdk_addr>INADDR_ANY</sdk_addr>
    <sdk_udp_port>14540</sdk_udp_port>
    <hil_mode>0</hil_mode>
    <hil_state_level>0</hil_state_level>
    <send_vision_estimation>0</send_vision_estimation>
    <send_odometry>1</send_odometry>
    <enable_lockstep>1</enable_lockstep>
    <use_tcp>1</use_tcp>
    <motorSpeedCommandPubTopic>/gazebo/command/motor_speed</motorSpeedCommandPubTopic>
    <control_channels>
      <channel name='rotor1'>
        <input_index>0</input_index>
        <input_offset>0</input_offset>
        <input_scaling>1000</input_scaling>
        <zero_position_disarmed>0</zero_position_disarmed>
        <zero_position_armed>100</zero_position_armed>
        <joint_control_type>velocity</joint_control_type>
      </channel>
      <channel name='rotor2'>
        <input_index>1</input_index>
        <input_offset>0</input_offset>
        <input_scaling>1000</input_scaling>
        <zero_position_disarmed>0</zero_position_disarmed>
        <zero_position_armed>100</zero_position_armed>
        <joint_control_type>velocity</joint_control_type>
      </channel>
      <channel name='rotor3'>
        <input_index>2</input_index>
        <input_offset>0</input_offset>
        <input_scaling>1000</input_scaling>
        <zero_position_disarmed>0</zero_position_disarmed>
        <zero_position_armed>100</zero_position_armed>
        <joint_control_type>velocity</joint_control_type>
      </channel>
      <channel name='rotor4'>
        <input_index>3</input_index>
        <input_offset>0</input_offset>
        <input_scaling>1000</input_scaling>
        <zero_position_disarmed>0</zero_position_disarmed>
        <zero_position_armed>100</zero_position_armed>
        <joint_control_type>velocity</joint_control_type>
      </channel>
    </control_channels>
  </plugin>
</gazebo>
<gazebo>
  <static>0</static>
</gazebo>
</robot>
